{"name": "test_3", "status": "failed", "statusDetails": {"message": "AssertionError: ++++ soft assert failure details follow below ++++\n\n++++++++++++++++++++++++++++++++++++++++++++++++++++++++++++++++++++++\nThe following failure was found in \"test_3\" (TestCases.test1.Test3):\n+----------------------+----------------------+----------------------+\nTraceback (most recent call last):\n  File \"E:\\Robot\\TestCases\\test1.py\", line 13, in test_3\n    self.soft_assert(self.assertEqual, 1 ,2)\n  File \"C:\\Users\\acer\\Lib\\site-packages\\softest\\case.py\", line 62, in soft_assert\n    assert_method(*arguments, **keywords)\n  File \"C:\\Users\\acer\\Lib\\unittest\\case.py\", line 885, in assertEqual\n    assertion_func(first, second, msg=msg)\n  File \"C:\\Users\\acer\\Lib\\unittest\\case.py\", line 878, in _baseAssertEqual\n    raise self.failureException(msg)\nAssertionError: 1 != 2\n\n-+ [1/1] +-", "trace": "self = <TestCases.test1.Test3 testMethod=test_3>\n\n    def test_3(self):\n        self.soft_assert(self.assertEqual, 1 ,2)\n        self.soft_assert(self.assertEqual, 2,2)\n>       self.assert_all()\n\nTestCases\\test1.py:15: \n_ _ _ _ _ _ _ _ _ _ _ _ _ _ _ _ _ _ _ _ _ _ _ _ _ _ _ _ _ _ _ _ _ _ _ _ _ _ _ _ _ _ _ _ _ _ _ _ _ _ _ _ _ _ _ _ _ _ _ _ _ _ _ _ _ _ _ _ _ _ _ _ _ _ _ _ _ _ _ _ _ _ _ _ _ _ _ _ \nC:\\Users\\acer\\Lib\\site-packages\\softest\\case.py:139: in assert_all\n    self.fail(''.join(failure_output))\nE   AssertionError: ++++ soft assert failure details follow below ++++\nE   \nE   ++++++++++++++++++++++++++++++++++++++++++++++++++++++++++++++++++++++\nE   The following failure was found in \"test_3\" (TestCases.test1.Test3):\nE   +----------------------+----------------------+----------------------+\nE   Traceback (most recent call last):\nE     File \"E:\\Robot\\TestCases\\test1.py\", line 13, in test_3\nE       self.soft_assert(self.assertEqual, 1 ,2)\nE     File \"C:\\Users\\acer\\Lib\\site-packages\\softest\\case.py\", line 62, in soft_assert\nE       assert_method(*arguments, **keywords)\nE     File \"C:\\Users\\acer\\Lib\\unittest\\case.py\", line 885, in assertEqual\nE       assertion_func(first, second, msg=msg)\nE     File \"C:\\Users\\acer\\Lib\\unittest\\case.py\", line 878, in _baseAssertEqual\nE       raise self.failureException(msg)\nE   AssertionError: 1 != 2\nE   \nE   -+ [1/1] +-"}, "start": 1717491625779, "stop": 1717491625779, "uuid": "9880dbf8-9164-4de3-8496-bdfbfbdc7c5a", "historyId": "2654be63eec6b6e80e47cf48573b457f", "testCaseId": "2654be63eec6b6e80e47cf48573b457f", "fullName": "TestCases.test1.Test3#test_3", "labels": [{"name": "parentSuite", "value": "TestCases"}, {"name": "suite", "value": "test1"}, {"name": "subSuite", "value": "Test3"}, {"name": "host", "value": "DESKTOP-03I0G8C"}, {"name": "thread", "value": "3452-MainThread"}, {"name": "framework", "value": "pytest"}, {"name": "language", "value": "cpython3"}, {"name": "package", "value": "TestCases.test1"}]}