{"name": "test_2", "status": "failed", "statusDetails": {"message": "AssertionError: ++++ soft assert failure details follow below ++++\n\n++++++++++++++++++++++++++++++++++++++++++++++++++++++++++++++++++++++\nThe following failure was found in \"test_2\" (TestCases.test1.Test2):\n+----------------------+----------------------+----------------------+\nTraceback (most recent call last):\n  File \"E:\\Robot\\TestCases\\test1.py\", line 5, in test_2\n    self.soft_assert(self.assertEqual, 2, 3)\n  File \"C:\\Users\\acer\\Lib\\site-packages\\softest\\case.py\", line 62, in soft_assert\n    assert_method(*arguments, **keywords)\n  File \"C:\\Users\\acer\\Lib\\unittest\\case.py\", line 885, in assertEqual\n    assertion_func(first, second, msg=msg)\n  File \"C:\\Users\\acer\\Lib\\unittest\\case.py\", line 878, in _baseAssertEqual\n    raise self.failureException(msg)\nAssertionError: 2 != 3\n\n-+ [1/1] +-", "trace": "self = <TestCases.test1.Test2 testMethod=test_2>\n\n    def test_2(self):\n        self.soft_assert(self.assertEqual, 2, 3)\n        print(\"Assertion Continue\")\n        self.soft_assert(self.assertEqual, 2, 2)\n>       self.assert_all()\n\nTestCases\\test1.py:8: \n_ _ _ _ _ _ _ _ _ _ _ _ _ _ _ _ _ _ _ _ _ _ _ _ _ _ _ _ _ _ _ _ _ _ _ _ _ _ _ _ _ _ _ _ _ _ _ _ _ _ _ _ _ _ _ _ _ _ _ _ _ _ _ _ _ _ _ _ _ _ _ _ _ _ _ _ _ _ _ _ _ _ _ _ _ _ _ _ \nC:\\Users\\acer\\Lib\\site-packages\\softest\\case.py:139: in assert_all\n    self.fail(''.join(failure_output))\nE   AssertionError: ++++ soft assert failure details follow below ++++\nE   \nE   ++++++++++++++++++++++++++++++++++++++++++++++++++++++++++++++++++++++\nE   The following failure was found in \"test_2\" (TestCases.test1.Test2):\nE   +----------------------+----------------------+----------------------+\nE   Traceback (most recent call last):\nE     File \"E:\\Robot\\TestCases\\test1.py\", line 5, in test_2\nE       self.soft_assert(self.assertEqual, 2, 3)\nE     File \"C:\\Users\\acer\\Lib\\site-packages\\softest\\case.py\", line 62, in soft_assert\nE       assert_method(*arguments, **keywords)\nE     File \"C:\\Users\\acer\\Lib\\unittest\\case.py\", line 885, in assertEqual\nE       assertion_func(first, second, msg=msg)\nE     File \"C:\\Users\\acer\\Lib\\unittest\\case.py\", line 878, in _baseAssertEqual\nE       raise self.failureException(msg)\nE   AssertionError: 2 != 3\nE   \nE   -+ [1/1] +-"}, "attachments": [{"name": "stdout", "source": "960bf1a9-4a99-4bc2-b091-8f01ae3789f4-attachment.txt", "type": "text/plain"}], "start": 1717491625591, "stop": 1717491625654, "uuid": "bb4f3957-d57a-45d6-91ad-a81d518ed9e5", "historyId": "867c69d17bb7f8105c73596e47bc6697", "testCaseId": "867c69d17bb7f8105c73596e47bc6697", "fullName": "TestCases.test1.Test2#test_2", "labels": [{"name": "parentSuite", "value": "TestCases"}, {"name": "suite", "value": "test1"}, {"name": "subSuite", "value": "Test2"}, {"name": "host", "value": "DESKTOP-03I0G8C"}, {"name": "thread", "value": "3452-MainThread"}, {"name": "framework", "value": "pytest"}, {"name": "language", "value": "cpython3"}, {"name": "package", "value": "TestCases.test1"}]}